Workbook

Sheet Dashboard
B2: Verified European Aerospace & Defence Technology Transactions
B3: Completed IPO and change-of-control transactions | 2023-01-01 to 2026-08-02 | Strict public-source verification
B5: Completed transactions | C5: =COUNTA('Europe'!A2:A134) | E5: Completion year | F5: Transactions
B6: M&A | C6: =COUNTIF('Europe'!K2:K134,"M&A") | E6: 2023 | F6: =COUNTIF('Europe'!J2:J134,E6)
B7: IPOs | C7: =COUNTIF('Europe'!K2:K134,"IPO") | E7: 2024 | F7: =COUNTIF('Europe'!J2:J134,E7)
B8: Pending pipeline | C8: =COUNTA('Europe_Pending'!A2:A15) | E8: 2025 | F8: =COUNTIF('Europe'!J2:J134,E8)
E9: 2026 | F9: =COUNTIF('Europe'!J2:J134,E9)
B11: Scope and audit controls
B12: Completed population | C12: Europe sheet only; sorted by completion/IPO date.
B13: Pending transactions | C13: Europe_Pending; excluded from completed KPIs.
B14: Exclusions and corrections | C14: Europe_Audit_Log records a decision for every original Europe row.
B15: Source record | C15: Sources_Audit and row-level primary URLs.
B16: Quality control | C16: Checks sheet reconciles IDs, dates, sources, status and Master_Deals.
B17: Completeness limitation | C17: Public sources cannot prove the absence of undisclosed private transactions; no unavailable value has been invented.
B19: Workbook navigation
B20: Europe | C20: Verified completed transactions
B21: Europe_Pending | C21: Announced but uncompleted transactions
B22: Europe_Audit_Log | C22: Every original row's retain/exclude/correct decision
B23: Sources_Audit | C23: Primary-source register
B24: Master_Deals | C24: All regions, with Europe reconciled
B25: Definitions | C25: Approved strict scope and conventions
B26: Checks | C26: Quality-control results

Sheet Master_Deals
A1: Deal ID | B1: Region | C1: Target Country | D1: Target / Asset | E1: Acquirer | F1: Acquirer Country | G1: Seller | H1: Announcement Date | I1: Completion Date | J1: Deal Year | K1: Transaction Type | L1: Deal Structure | M1: Deal Status | N1: Deal Value (USD mn) | O1: Currency | P1: Hardware / Software / Services | Q1: A&D Domain | R1: Inclusion Tier | S1: Relevance Rationale | T1: Reliability | U1: Source URL | V1: Source Type | W1: Notes
A2: ISR-001 | B2: Israel | C2: Israel | D2: Orbit Communication Systems | E2: Kratos Defense & Security Solutions | F2: USA | G2: Public shareholders | H2: 2025-11-04 | I2: Expected 2026 | J2: 2026 | K2: M&A | L2: Full acquisition | M2: Announced | N2: 356.3 | O2: USD | P2: Hardware | Q2: Satellite communications / defense satcom | R2: Core A&D | S2: Israeli satellite-communications and airborne/ground satcom provider with defense and national-security applications. | T2: High | U2: https://www.kratosdefense.com/newsroom/kratos-to-acquire-israel-based-orbit-technologies-ltd-for-356-3-million | V2: Company / reputable press
A3: ISR-002 | B3: Israel | C3: Israel | D3: Sentry CS / Sentrycs | E3: Ondas Holdings | F3: USA | H3: 2025-11-04 | I3: 2025-11-29 | J3: 2025 | K3: M&A | L3: Full acquisition | M3: Completed | O3: USD | P3: Software/Hardware | Q3: Counter-UAS / RF cyber | R3: Core A&D | S3: Counter-drone detection and mitigation for defense, homeland security, airports, and critical infrastructure. | T3: High | U3: https://ir.ondas.com/press-releases/detail/251/ondas-to-acquire-sentrycs-a-global-leader-in-counter-uas | V3: Company / reputable press
A4: ISR-003 | B4: Israel | C4: Israel | D4: Roboteam | E4: Ondas Holdings | F4: USA | H4: 2025-11-25 | I4: 2025-12-17 | J4: 2025 | K4: M&A | L4: Full acquisition | M4: Completed | O4: USD | P4: Hardware | Q4: UGV / tactical robotics | R4: Core A&D | S4: Unmanned ground vehicles for military, EOD, ISR, and hazardous missions. | T4: High | U4: https://ir.ondas.com/press-releases/detail/264/ondas-completes-acquisition-of-roboteam-a-global-leader-in | V4: Company / reputable press
A5: ISR-004 | B5: Israel | C5: Israel | D5: Omnisys | E5: Ondas Holdings | F5: USA | H5: 2026-05-18 | J5: 2026 | K5: M&A | L5: Full acquisition / stock deal | M5: Announced | N5: 200 | O5: USD | P5: Software | Q5: Mission planning / C2 / battlefield optimization | R5: Core A&D | S5: Military mission-planning and operational-optimization software for defense customers. | T5: Medium-High | U5: https://www.calcalistech.com/ctechnews/article/skbzd9dkge | V5: Business press | W5: Very recent; verify closing when announced.
A6: ISR-005 | B6: Israel | C6: Israel | D6: SpearUAV | E6: UVision Air | F6: Israel | H6: 2025-12-08 | J6: 2025 | K6: M&A | L6: Acquisition | M6: Announced / reported | O6: USD | P6: Hardware | Q6: Loitering munitions / tactical UAV | R6: Core A&D | S6: Capsule-launched tactical drones/loitering systems; directly defense-relevant. | T6: Medium-High | U6: https://www.globes.co.il/news/article.aspx?did=1001528671 | V6: Business press | W6: Value undisclosed in public reporting.
A7: ISR-006 | B7: Israel | C7: Israel | D7: Iron Drone | E7: Airobotics / Ondas Holdings | F7: Israel / USA | H7: 2023-03-06 | J7: 2023 | K7: M&A | L7: Acquisition | M7: Completed | O7: USD | P7: Hardware/Software | Q7: Counter-UAS / autonomous drones | R7: Core A&D | S7: Counter-drone interception and autonomous drone capabilities relevant to security and defense. | T7: Medium | U7: https://ir.ondas.com/press-releases/detail/172/ondas-receives-8-0-million-purchase-order-for-iron-drone | V7: Company press release | W7: Use if source URL resolves in browser.
A8: ISR-007 | B8: Israel | C8: Israel | D8: Airobotics | E8: Ondas Holdings | F8: USA | G8: Public shareholders | H8: 2022-07-05 | I8: 2023-01-23 | J8: 2023 | K8: M&A | L8: Full acquisition | M8: Completed | O8: USD | P8: Hardware/Software | Q8: Autonomous drone systems | R8: Adjacent dual-use | S8: Autonomous drones for security, public-safety and critical-infrastructure missions; not a pure defense transaction. | T8: Medium-High | U8: https://ir.ondas.com/press-releases/detail/108/ondas-holdings-completes-acquisition-of-airobotics | V8: Company press release
A9: ISR-008 | B9: Israel | C9: Israel | D9: 4M defense | E9: Ondas Holdings | F9: USA | H9: 2025-09-03 | J9: 2025 | K9: M&A | L9: Acquisition | M9: Announced | O9: USD | P9: Software | Q9: Geospatial / infrastructure intelligence | R9: Adjacent dual-use | S9: Subsurface mapping/geospatial data can support infrastructure, security and resilience use cases; weaker defense fit than UAS/C2. | T9: Medium | U9: https://ir.ondas.com/press-releases/detail/249/ondas-to-acquire-controlling-interest-in-4m-defense | V9: Company press releases index | W9: Check final deal page before publication.
A10: ISR-010 | B10: Israel | C10: USA | D10: DataPath | E10: Gilat Satellite Networks | F10: Israel | G10: DataPath shareholders | H10: 2023-03-09 | I10: 2023-11-15 | J10: 2023 | K10: M&A | L10: Full acquisition | M10: Completed | O10: USD | P10: Hardware/Services | Q10: Satellite communications / defense satcom | R10: Core A&D | S10: US satellite communications systems provider serving defense and government customers acquired by Israeli satcom group. | T10: High | U10: https://www.gilat.com/pressreleases/gilat-completes-acquisition-of-datapath/ | V10: Company press release
A11: ISR-011 | B11: Israel | C11: USA | D11: Stellar Blu Solutions | E11: Gilat Satellite Networks | F11: Israel | H11: 2024-06-17 | I11: 2024-09-18 | J11: 2024 | K11: M&A | L11: Full acquisition | M11: Completed | O11: USD | P11: Hardware | Q11: Aviation connectivity / satcom terminals | R11: Adjacent A&D aerospace | S11: Aviation satcom terminal business relevant to aerospace connectivity; dual-use rather than pure defense. | T11: High | U11: https://www.gilat.com/pressreleases/gilat-completes-acquisition-of-stellar-blu-solutions-llc/ | V11: Company press release
A12: ISR-014 | B12: Israel | C12: Israel | D12: CyberArk | E12: Palo Alto Networks | F12: USA | G12: Public shareholders | H12: 2025-07-30 | I12: Expected FY2026 | J12: 2026 | K12: M&A | L12: Cash-and-stock acquisition | M12: Announced | N12: 25000 | O12: USD | P12: Software | Q12: Identity security / privileged access | R12: Adjacent cyber-security | S12: Large Israeli-founded cybersecurity deal; relevant to defense/security landscape but not pure aerospace/defense. | T12: High | U12: https://www.reuters.com/world/middle-east/palo-altos-25-billion-deal-cyberark-targets-rising-ai-driven-threats-2025-07-30/?utm_source=chatgpt.com | V12: Company press release
A13: ISR-015 | B13: Israel | C13: Israel-founded / USA | D13: Wiz | E13: Google / Alphabet | F13: USA | H13: 2025-03-18 | I13: Pending / approvals | J13: 2025 | K13: M&A | L13: Full acquisition | M13: Announced | N13: 32000 | O13: USD | P13: Software | Q13: Cloud security | R13: Adjacent cyber-security | S13: Israeli-founded cloud security company; relevant as dual-use cyber/security consolidation, not core A&D. | T13: High | U13: https://blog.google/company-news/inside-google/company-announcements/google-agreement-acquire-wiz/?utm_source=chatgpt.com | V13: Company press release
A14: ISR-016 | B14: Israel | C14: Israel | D14: Dig Security | E14: Palo Alto Networks | F14: USA | H14: 2023-10-31 | J14: 2023 | K14: M&A | L14: Acquisition | M14: Completed | N14: 350 | O14: USD | P14: Software | Q14: Cloud data security / DSPM | R14: Adjacent cyber-security | S14: Israeli cybersecurity acquisition; relevant to security/dual-use cyber but not pure defense. | T14: Medium-High | U14: https://www.paloaltonetworks.com/company/press/2023/palo-alto-networks-completes-acquisition-of-dig-security?utm_source=chatgpt.com | V14: Legal adviser / business press | W14: Value usually reported as $300m-$400m; use midpoint.
A15: ISR-017 | B15: Israel | C15: Israel | D15: Talon Cyber Security | E15: Palo Alto Networks | F15: USA | H15: 2023-11-06 | J15: 2023 | K15: M&A | L15: Acquisition | M15: Completed | N15: 625 | O15: USD | P15: Software | Q15: Secure enterprise browser | R15: Adjacent cyber-security | S15: Browser-security acquisition; relevant to cyber/security consolidation. | T15: Medium-High | U15: https://www.calcalistech.com/ctechnews/article/r1hd0o87a?utm_source=chatgpt.com | V15: Business press | W15: Reported value.
A16: ISR-018 | B16: Israel | C16: Israel | D16: Noname Security | E16: Akamai Technologies | F16: USA | H16: 2024-05-07 | I16: 2024-06-25 | J16: 2024 | K16: M&A | L16: Full acquisition | M16: Completed | N16: 450 | O16: USD | P16: Software | Q16: API security | R16: Adjacent cyber-security | S16: API-security platform acquired by major security infrastructure company; dual-use cybersecurity relevance. | T16: High | U16: https://www.akamai.com/newsroom/press-release/akamai-completes-acquisition-of-api-security-company-noname?utm_source=chatgpt.com | V16: Company press release
A17: ISR-019 | B17: Israel | C17: Israel | D17: Perimeter 81 | E17: Check Point Software Technologies | F17: Israel | H17: 2023-08-10 | I17: 2023-09-11 | J17: 2023 | K17: M&A | L17: Acquisition | M17: Completed | N17: 490 | O17: USD | P17: Software | Q17: SASE / network security | R17: Adjacent cyber-security | S17: Israeli network-security/SASE acquisition; relevant to homeland-security and enterprise-cyber landscape. | T17: High | U17: https://www.checkpoint.com/press-releases/check-point-to-acquire-perimeter-81-to-deliver-the-fastest-and-most-secure-sase-solution-in-the-industry/?utm_source=chatgpt.com | V17: Company press release
A18: ISR-020 | B18: Israel | C18: Israel | D18: Ermetic | E18: Tenable | F18: USA | H18: 2023-09-07 | I18: 2023-10-02 | J18: 2023 | K18: M&A | L18: Acquisition | M18: Completed | N18: 265 | O18: USD | P18: Software | Q18: Cloud infrastructure entitlement management | R18: Adjacent cyber-security | S18: Cloud security and identity-risk platform; dual-use cyber relevance. | T18: High | U18: https://www.tenable.com/press-releases/tenable-announces-intent-to-acquire-ermetic?utm_source=chatgpt.com | V18: Company press release
A19: ISR-021 | B19: Israel | C19: Israel | D19: Axis Security | E19: Hewlett Packard Enterprise | F19: USA | H19: 2023-03-02 | I19: 2023-03-31 | J19: 2023 | K19: M&A | L19: Acquisition | M19: Completed | N19: 500 | O19: USD | P19: Software | Q19: SASE / secure access | R19: Adjacent cyber-security | S19: Secure access / edge cybersecurity relevant to security infrastructure; not pure A&D. | T19: Medium-High | U19: https://en.globes.co.il/en/article-hpe-buys-israeli-co-axis-security-for-500m-1001440101?utm_source=chatgpt.com | V19: Company press release | W19: Reported value from business press; official release may not disclose price.
A20: ISR-022 | B20: Israel | C20: Israel | D20: Avalor | E20: Zscaler | F20: USA | H20: 2024-03-13 | I20: 2024-03-26 | J20: 2024 | K20: M&A | L20: Acquisition | M20: Completed | N20: 350 | O20: USD | P20: Software | Q20: Security data fabric / exposure management | R20: Adjacent cyber-security | S20: Israeli security-data platform acquired by Zscaler; relevant to cyber-security consolidation. | T20: High | U20: https://www.calcalistech.com/ctechnews/article/b1jvqdgr6?utm_source=chatgpt.com | V20: Company press release
A21: ISR-023 | B21: Israel | C21: Israel | D21: Gem Security | E21: Wiz | F21: Israel-founded / USA | H21: 2024-04-10 | J21: 2024 | K21: M&A | L21: Acquisition | M21: Completed | N21: 350 | O21: USD | P21: Software | Q21: Cloud detection and response | R21: Adjacent cyber-security | S21: Cloud threat-detection acquisition by Israeli-founded security platform Wiz. | T21: Medium-High | U21: https://www.calcalistech.com/ctechnews/article/bjleedj0t?utm_source=chatgpt.com | V21: Company blog / press
A22: ISR-024 | B22: Israel | C22: Israel | D22: Laminar | E22: Rubrik | F22: USA | H22: 2023-08-08 | J22: 2023 | K22: M&A | L22: Acquisition | M22: Completed | N22: 200 | O22: USD | P22: Software | Q22: Cloud data security | R22: Adjacent cyber-security | S22: Cloud data-security acquisition; dual-use cyber relevance. | T22: High | V22: Company press release | W22: Reported value around $200m-$250m.
A23: ISR-025 | B23: Israel | C23: Israel | D23: Flow Security | E23: CrowdStrike | F23: USA | H23: 2024-03-05 | J23: 2024 | K23: M&A | L23: Acquisition | M23: Completed | N23: 200 | O23: USD | P23: Software | Q23: Cloud data runtime security | R23: Adjacent cyber-security | S23: Cloud data-security acquisition by CrowdStrike; relevant to cyber/security but not pure A&D. | T23: Medium-High | V23: Company press release | W23: Reported value from business press.
A24: ISR-026 | B24: Israel | C24: Israel | D24: Bionic | E24: CrowdStrike | F24: USA | H24: 2023-09-19 | J24: 2023 | K24: M&A | L24: Acquisition | M24: Completed | N24: 350 | O24: USD | P24: Software | Q24: Application security posture management | R24: Adjacent cyber-security | S24: Israeli app-security company acquired by CrowdStrike; security-adjacent. | T24: High | V24: Company press release
A25: ISR-028 | B25: Israel | C25: Israel | D25: Spera Security | E25: Okta | F25: USA | H25: 2023-12-19 | I25: 2024-02-01 | J25: 2024 | K25: M&A | L25: Acquisition | M25: Completed | N25: 110 | O25: USD | P25: Software | Q25: Identity security posture management | R25: Adjacent cyber-security | S25: Identity-security posture management; relevant to cyber/zero-trust security. | T25: High | V25: Company press release
A26: ISR-029 | B26: Israel | C26: Israel | D26: SCADAfence | E26: Honeywell | F26: USA | H26: 2023-07-10 | I26: 2023-08-14 | J26: 2023 | K26: M&A | L26: Acquisition | M26: Completed | O26: USD | P26: Software | Q26: OT / industrial cybersecurity | R26: Adjacent cyber / critical infrastructure | S26: OT cybersecurity for industrial and critical infrastructure environments; strong homeland-security relevance. | T26: High | V26: Company press release
A27: ISR-032 | B27: Israel | C27: Israel | D27: Enso Security | E27: Snyk | F27: UK / USA | H27: 2023-06-20 | J27: 2023 | K27: M&A | L27: Acquisition | M27: Completed | O27: USD | P27: Software | Q27: Application security posture management | R27: Adjacent cyber-security | S27: Israeli application-security posture management acquired by Snyk; cyber-security fit. | T27: High | V27: Company press release
A28: ISR-033 | B28: Israel | C28: Israel | D28: Silk Security | E28: Armis | F28: Israel / USA | H28: 2024-04-17 | J28: 2024 | K28: M&A | L28: Acquisition | M28: Completed | N28: 150 | O28: USD | P28: Software | Q28: Cyber risk prioritization | R28: Adjacent cyber-security | S28: Cyber-risk prioritization platform acquired by Armis; security-adjacent. | T28: High | V28: Company press release | W28: Reported value from business press.
A29: ISR-034 | B29: Israel | C29: Israel | D29: Authomize | E29: Delinea | F29: USA | H29: 2024-01-09 | I29: 2024-02-01 | J29: 2024 | K29: M&A | L29: Acquisition | M29: Completed | O29: USD | P29: Software | Q29: Identity threat detection and response | R29: Adjacent cyber-security | S29: Identity-security and threat-detection acquisition; cyber-security fit. | T29: High | V29: Company press release
A30: USA-040 | B30: USA | C30: USA | D30: Spirit AeroSystems | E30: Boeing | F30: USA | G30: Public shareholders | H30: 2024-07-01 | I30: 2025-12-08 | J30: 2025 | K30: M&A | L30: Full acquisition | M30: Completed | N30: 4700 | O30: USD | P30: Hardware | Q30: Aerospace structures / supply chain | R30: Core aerospace | S30: Major aerospace structures supplier; central to aircraft production supply chain. | T30: High | V30: Company press release / Reuters | W30: Enterprise value often cited around $8.3bn including debt.
A31: USA-041 | B31: USA | C31: USA | D31: CAES Systems | E31: Honeywell | F31: USA | G31: Advent International | H31: 2024-06-20 | I31: 2024-09-04 | J31: 2024 | K31: M&A | L31: Full acquisition | M31: Completed | N31: 1900 | O31: USD | P31: Hardware | Q31: RF electronics / defense electronics | R31: Core A&D | S31: High-reliability RF, antenna and communications electronics used across defense platforms. | T31: High | V31: Company press release
A32: USA-042 | B32: USA | C32: USA | D32: BlueHalo | E32: AeroVironment | F32: USA | G32: Arlington Capital Partners | H32: 2024-11-19 | I32: 2025-05-01 | J32: 2025 | K32: M&A | L32: Stock transaction / merger | M32: Completed | N32: 4100 | O32: USD | P32: Hardware/Software | Q32: C-UAS / directed energy / space / cyber | R32: Core A&D | S32: Creates defense-tech portfolio across uncrewed systems, counter-UAS, directed energy, cyber and space. | T32: High | V32: Company press release
A33: USA-043 | B33: USA | C33: USA | D33: LinQuest | E33: KBR | F33: USA | G33: Madison Dearborn Partners | H33: 2024-07-16 | I33: 2024-09-03 | J33: 2024 | K33: M&A | L33: Full acquisition | M33: Completed | N33: 737 | O33: USD | P33: Services/Software | Q33: National security space / digital integration | R33: Core A&D services | S33: Engineering, data analytics and digital integration for national-security space missions. | T33: High | V33: Company press release
A34: USA-044 | B34: USA | C34: USA | D34: SciTec | E34: Firefly Aerospace | F34: USA | H34: 2025-10-05 | I34: Expected 2025 | J34: 2025 | K34: M&A | L34: Cash and stock acquisition | M34: Announced | N34: 855 | O34: USD | P34: Software/Services | Q34: Missile warning / tracking / remote sensing | R34: Core A&D space | S34: National-security technology company focused on missile warning, tracking, ISR and space defense analytics. | T34: High | V34: Reuters
A35: USA-045 | B35: USA | C35: USA | D35: Stellant Systems | E35: TransDigm Group | F35: USA | G35: Arlington Capital Partners | H35: 2025-12-31 | J35: 2025 | K35: M&A | L35: Full acquisition | M35: Announced | N35: 960 | O35: USD | P35: Hardware | Q35: Electronic components / RF / space | R35: Core A&D | S35: High-power electronic components and subsystems for aerospace, defense, space and satellite applications. | T35: High | V35: Reuters
A36: USA-046 | B36: USA | C36: USA | D36: Raptor Scientific | E36: TransDigm Group | F36: USA | G36: L Squared Capital Partners | H36: 2023-05-30 | I36: 2023-08-09 | J36: 2023 | K36: M&A | L36: Full acquisition | M36: Completed | N36: 655 | O36: USD | P36: Hardware/Services | Q36: Aerospace testing and measurement | R36: Core aerospace/defense | S36: Testing and measurement systems for aerospace and defense platforms. | T36: High | V36: Company press release
A37: USA-047 | B37: USA | C37: USA | D37: Calspan Corporation | E37: TransDigm Group | F37: USA | G37: Public / private owners | H37: 2023-03-14 | I37: 2023-05-08 | J37: 2023 | K37: M&A | L37: Full acquisition | M37: Completed | N37: 725 | O37: USD | P37: Services/Hardware | Q37: Aerospace testing / wind tunnel / flight test | R37: Core aerospace/defense | S37: Aerospace testing and technology-development services for defense and commercial aviation. | T37: High | V37: Company press release
A38: USA-048 | B38: USA | C38: USA | D38: Wencor Group | E38: HEICO Corporation | F38: USA | G38: Warburg Pincus | H38: 2023-05-15 | I38: 2023-08-04 | J38: 2023 | K38: M&A | L38: Full acquisition | M38: Completed | N38: 2050 | O38: USD | P38: Hardware/Services | Q38: Aerospace aftermarket / parts distribution | R38: Core aerospace | S38: Aviation aftermarket components and distribution serving commercial and defense aviation customers. | T38: High | V38: Company press release
A39: USA-050 | B39: USA | C39: USA | D39: Adranos | E39: Anduril Industries | F39: USA | H39: 2023-06-25 | J39: 2023 | K39: M&A | L39: Acquisition | M39: Completed | O39: USD | P39: Hardware | Q39: Solid rocket motors / propulsion | R39: Core A&D | S39: Solid rocket motor and energetic-materials technology for missiles and defense systems. | T39: High | V39: Company press release
A40: USA-051 | B40: USA | C40: USA | D40: Blue Force Technologies | E40: Anduril Industries | F40: USA | H40: 2023-09-07 | J40: 2023 | K40: M&A | L40: Acquisition | M40: Completed | O40: USD | P40: Hardware/Software | Q40: Autonomous aircraft / defense aviation | R40: Core A&D | S40: Developer of autonomous aircraft; fits US defense-tech autonomy and air systems. | T40: High | V40: Company press release
...

Sheet Israel M&A NOT
A1: Count of Target / Asset | B1: Transaction Type
A2: Deal Year | B2: M&A | C2: M&A / LOI | D2: M&A / Majority stake | E2: Merger/Acquisition | F2: Other / SPAC business combination | G2: Total Result
A3: 2023 | B3: 16 | E3: 1 | G3: 17
A4: 2024 | B4: 13 | E4: 1 | G4: 14
A5: 2025 | B5: 17 | C5: 1 | E5: 4 | G5: 22
A6: 2026 | B6: 14 | D6: 1 | F6: 1 | G6: 16
A7: Total Result | B7: 60 | C7: 1 | D7: 1 | E7: 6 | F7: 1 | G7: 69

Sheet Israel M&A Deal Amounts
A1: Sum of Deal Value (USD mn) | B1: Transaction Type
A2: Deal Year | B2: M&A | C2: M&A / LOI | D2: M&A / Majority stake | E2: Merger/Acquisition | F2: Other / SPAC business combination | G2: Total Result
A3: 2023 | B3: 2884.66 | G3: 2884.66
A4: 2024 | B4: 1933.01 | G4: 1933.01
A5: 2025 | B5: 32594.4 | G5: 32594.4
A6: 2026 | B6: 28404.34 | D6: 9.4 | F6: 1500 | G6: 29913.74
A7: Total Result | B7: 65816.41 | D7: 9.4 | F7: 1500 | G7: 67325.81

Sheet Israel
A1: Deal ID | B1: Region | C1: Target Country | D1: Target / Asset | E1: Acquirer | F1: Acquirer Country | G1: Seller | H1: Announcement Date | I1: Completion Date | J1: Deal Year | K1: Transaction Type | L1: Deal Structure | M1: Deal Status | N1: Deal Value (USD mn) | O1: Currency | P1: Hardware / Software / Services | Q1: A&D Domain | R1: Inclusion Tier | S1: Relevance Rationale | T1: Reliability | U1: Source URL | V1: Source Type | W1: Notes | X1: Implied EV/Revenue | Y1: Implied EV/EBITDA | Z1: Deal Size/EBITDA | AA1: EBITDA | AB1: Deal Size/Revenue | AC1: Revenue | AD1: Deal Type 2 | AE1: Post Valuation | AF1: Deal Synopsis | AG1: Financing Status | AH1: Business Status | AI1: Investors | AJ1: Primary PitchBook Industry Code | AK1: Verticals | AL1: Description | AM1: HQ Location | AN1: Company Website
B2: Israel | C2: Israel | D2: Orbit Communication Systems | E2: Kratos Defense & Security Solutions | F2: USA | G2: Public shareholders | H2: 2025-11-04 | I2: Expected 2026 | J2: 2026 | K2: M&A | L2: Full acquisition | M2: Announced | N2: 356.3 | O2: USD | P2: Hardware | Q2: Satellite/Space | R2: Core A&D | S2: Israeli satellite-communications and airborne/ground satcom provider with defense and national-security applications. | T2: High | U2: https://www.kratosdefense.com/newsroom/kratos-to-acquire-israel-based-orbit-technologies-ltd-for-356-3-million | V2: Company / reputable press | X2: 3.81 | Y2: 17 | Z2: 19.12 | AA2: 18.63 | AB2: 4.29 | AC2: 83.03 | AE2: 356.3 | AF2: The company (TAE: ORBI) was acquired by Kratos Defense & Security Solutions (NAS: KTOS) for $356.3 million on March 17, 2026. This acquisition will deepen Kratos Defense & Security Solutions' presence in Israel and expand its reach across global defense and satellite communications markets. | AG2: Corporate Backed or Acquired | AH2: Generating Revenue | AI2: Kratos Defense & Security Solutions (NAS: KTOS) (Eric Demarco) | AJ2: Telecommunications Service Providers | AK2: Space Technology, TMT | AL2: Orbit Technologies Ltd is a provider of airborne communications, satellite-tracking, maritime, ground-station and new space solutions for commercial and government establishments. Its products include Audio Management System, Maritime SATCOM, Airborne Audio Management System, Maritime SATCOM, etc. | AM2: Netanya, Israel | AN2: www.orbit-cs-usa.com
B3: Israel | C3: Israel | D3: Omnisys | E3: Ondas Holdings | F3: USA | H3: 2026-05-18 | J3: 2026 | K3: M&A | L3: Full acquisition / stock deal | M3: Announced | N3: 200 | O3: USD | P3: Software | Q3: C4I/Mission Software | R3: Core A&D | S3: Military mission-planning and operational-optimization software for defense customers. | T3: Medium-High | U3: https://www.calcalistech.com/ctechnews/article/skbzd9dkge | V3: Business press | W3: Very recent; verify closing when announced.
B4: Israel | C4: Israel | D4: CyberArk | E4: Palo Alto Networks | F4: USA | G4: Public shareholders | H4: 2025-07-30 | I4: Expected FY2026 | J4: 2026 | K4: M&A | L4: Cash-and-stock acquisition | M4: Announced | N4: 25000 | O4: USD | P4: Software | Q4: Cybersecurity | R4: Adjacent cyber-security | S4: Large Israeli-founded cybersecurity deal; relevant to defense/security landscape but not pure aerospace/defense. | T4: High | U4: https://www.reuters.com/world/middle-east/palo-altos-25-billion-deal-cyberark-targets-rising-ai-driven-threats-2025-07-30/?utm_source=chatgpt.com | V4: Company press release
B5: Israel | C5: Israel | D5: BIRD Aerosystems | E5: Ondas Holdings | F5: USA | G5: FIMI / shareholders | H5: 2026-03-11 | I5: 2026-03-11 | J5: 2026 | K5: M&A | L5: FULL | M5: Completed / announced as acquired | N5: 133 | O5: USD | P5: Hardware / Software | Q5: Airborne Systems | R5: Core A&D | S5: Adds a true defense / airborne protection transaction, not cyber. Useful for airborne ISR, aircraft protection, and counter-UAS adjacency. | T5: High | U5: https://ir.ondas.com/press-releases/detail/289/ondas-acquires-bird-aerosystems-to-expand-airborne-missile | V5: Company press release + reputable press | W5: Deal value should be marked as reported by press/source support; keep as supplemental addition. | AF5: The company was acquired by Ondas (NAS: ONDS) for an undisclosed amount on March 11, 2026. | AG5: Formerly PE-Backed | AH5: Generating Revenue | AI5: Ondas (NAS: ONDS) (Eric Brock) | AJ5: Air | AK5: Industrials | AL5: Provider of airborne missile protection systems and airborne surveillance services for clients in commercial, governmental, military, and transnational organizations. The company's system engages in developing airborne missile protection systems and airborne surveillance, as well as information and observation applications that provide operational analysis, system design, integration, and installation through ground and flight testing, thereby enabling organizations to receive products that would protect them and ensure the security of their assets. | AM5: Herzliya, Israel | AN5: www.birdaero.com
B6: Israel | C6: Israel | D6: INDO Earth Moving Ltd. | E6: Ondas Holdings | F6: USA | G6: INDO shareholders | H6: 2026-03-17 | I6: 2026-03-17 | J6: 2026 | K6: M&A | L6: FULL | M6: Completed / announced as acquired | N6: Not disclosed | O6: USD | P6: Hardware / Services | Q6: Ground/Robotic Systems | R6: Core A&D / Defense services | S6: Adds non-cyber ground systems / military engineering exposure. Keep value blank to avoid mistaking program value for deal value. | T6: High | U6: https://ir.ondas.com/press-releases/detail/292/ondas-acquires-indo-earth-moving-ltd-following-its-140 | V6: Company press release | W6: Value not disclosed; do not use contract/program value as acquisition value. | AF6: The company was acquired by Ondas (NAS: ONDS) for an undisclosed amount on March 17, 2026. The acquisition represents an important step in the Ondas 's strategy to expand its portfolio of advanced autonomous technologies and robotic systems designed for mission-critical defense and infrastructure operations worldwide. | AG6: Corporate Backed or Acquired | AH6: Generating Revenue | AI6: Ondas (NAS: ONDS) (Eric Brock) | AJ6: Aerospace and Defense | AL6: Provider of heavy engineering equipment procurement and integration services intended to serve military and national infrastructure. The company provides sourcing, engineering integration, testing and lifecycle support of complex platforms and systems. | AM6: Maale Gilboa, Israel
B7: Israel | C7: Israel | D7: XTEND | E7: JFB Construction Holdings | F7: USA | G7: XTEND shareholders / JFB | H7: 2026-02-17 | I7: Expected mid-2026 | J7: 2026 | K7: IPO | L7: OTHER — all-stock merger / public listing | M7: Announced / expected close | N7: 1500 | O7: USD | P7: Hardware / Software | Q7: UAVs/Autonomous Systems | R7: Core A&D / Public-market transaction | S7: Adds a major drone/defense robotics transaction. Treat separately from traditional M&A because it is a merger to take XTEND public. | T7: High | U7: https://www.reuters.com/business/aerospace-defense/eric-trump-invests-israeli-drone-maker-xtends-merger-with-florida-construction-2026-02-17/ | V7: Reuters / reputable press | W7: Not classic M&A; classify as Other / public-market business combination.
B8: Israel | C8: Israel | D8: Nimbus Drones Technologies and Marketing Ltd. | E8: Nukkleus Inc. | F8: USA | G8: Elad Defense LLC | H8: 2026-01-15 | I8: 2026-01-15 | J8: 2026 | K8: M&A | L8: FULL | M8: Completed at signing | N8: 3.25 | O8: USD | P8: Hardware / Services | Q8: UAVs/Autonomous Systems | R8: Core A&D / UAV & Counter-UAS | S8: Adds a small but very relevant Israeli UAV/counter-UAS acquisition with contract-level source details. | T8: High | U8: https://contracts.justia.com/companies/brilliant-acquisition-corp-10112/contract/1353910/ | V8: Legal contract / transaction agreement | W8: Keep value blank unless consideration is clearly stated in agreement. | AC8: 0.94 | AF8: The company was acquired by Nukkleus (NAS: NUKK) for an undisclosed amount on January 16, 2026. The acquisition helps Nukkleus strengthen its defense technology portfolio. | AG8: Corporate Backed or Acquired | AH8: Generating Revenue | AI8: T3 Defense (NAS: DFNS) | AJ8: Aerospace and Defense | AL8: Provider of unmanned aerial vehicle services intended to serve defense and military organizations, public sector agencies, commercial industries, and agricultural clients. The company offers a range of services, including drone and repair laboratory operations, enterprise and consumer unmanned aerial vehicles, mapping and surveying, including orthophotos and three-dimensional models, aerial photography, red-team simulation for defense exercises, licensed drone training and certification, and counter-unmanned aerial systems research and development. | AM8: Netanya, Israel | AN8: nimbusd.co.il
B9: Israel | C9: Israel | D9: Aero Sol Aviation Solutions Ltd. | E9: Veloryx | F9: Israel | G9: Aero Sol shareholders | H9: 2026-03-15 | I9: Targeted April 2026 / pending binding agreement | J9: 2026 | K9: M&A / Majority stake | L9: Proposed 70% controlling stake | M9: Advanced negotiations / pending | N9: 9.4 | O9: USD | P9: Hardware / Software | Q9: UAVs/Autonomous Systems | R9: Core/Adjacent A&D — Pending | S9: Interesting non-cyber Israeli drone/control-stake transaction, but mark pending until binding agreement/closing is confirmed. | T9: Medium | U9: https://www.jpost.com/defense-and-tech/article-889954 | V9: Reputable press | W9: Pending / advanced negotiations; do not count as completed M&A.
B10: Israel | C10: Israel | D10: Sentry CS / Sentrycs | E10: Ondas Holdings | F10: USA | H10: 2025-11-04 | I10: 2025-11-29 | J10: 2025 | K10: M&A | L10: Full acquisition | M10: Completed | N10: 224.6 | O10: USD | P10: Software/Hardware | Q10: UAVs/Autonomous Systems | R10: Core A&D | S10: Counter-drone detection and mitigation for defense, homeland security, airports, and critical infrastructure. | T10: High | U10: https://ir.ondas.com/press-releases/detail/251/ondas-to-acquire-sentrycs-a-global-leader-in-counter-uas | V10: Company / reputable press | AB10: 20.99 | AC10: 10.7 | AE10: 224.6 | AF10: The company was acquired by Ondas Holdings (NAS: ONDS) for $224.6 million on November 17, 2025. | AG10: Formerly PE-Backed | AH10: Generating Revenue | AI10: Ondas (NAS: ONDS) (Eric Brock) | AJ10: Aerospace and Defense | AK10: Manufacturing, Robotics and Drones | AL10: Manufacturer of autonomous counter-drone systems designed to safeguard defense forces, public safety agencies and critical infrastructure from unauthorized aerial threats. The company develops protocol manipulation-based technology that detects, identifies, tracks and safely mitigates rogue drones without interference or collateral damage, enabling clients to secure their airspace. | AM10: Tel Aviv, Israel | AN10: www.sentrycs.com
B11: Israel | C11: Israel | D11: Roboteam | E11: Ondas Holdings | F11: USA | H11: 2025-11-25 | I11: 2025-12-17 | J11: 2025 | K11: M&A | L11: Full acquisition | M11: Completed | N11: 81.7 | O11: USD | P11: Hardware | Q11: Ground/Robotic Systems | R11: Core A&D | S11: Unmanned ground vehicles for military, EOD, ISR, and hazardous missions. | T11: High | U11: https://ir.ondas.com/press-releases/detail/264/ondas-completes-acquisition-of-roboteam-a-global-leader-in | V11: Company / reputable press | AF11: The company was acquired by Ondas Holdings (NAS: ONDS) for an undisclosed amount on December 17, 2025. | AG11: Formerly VC-backed | AH11: Generating Revenue | AI11: Ondas (NAS: ONDS) (Eric Brock) | AJ11: Aerospace and Defense | AK11: Advanced Manufacturing, Robotics and Drones | AL11: Developer of human-driven robot technology designed to offer tactical ground robotic systems. The company's technology designs, develops, and manufactures remote-controlled unmanned UGVs for defense, law enforcement, and public safety missions, enabling militants to get robots that address real human needs and save lives. | AM11: Petah Tikva, Israel | AN11: www.robo-team.com
B12: Israel | C12: Israel | D12: SpearUAV | E12: UVision Air | F12: Israel | H12: 2025-12-08 | J12: 2025 | K12: M&A | L12: Acquisition | M12: Announced / reported | N12: Not disclosed | O12: USD | P12: Hardware | Q12: UAVs/Autonomous Systems | R12: Core A&D | S12: Capsule-launched tactical drones/loitering systems; directly defense-relevant. | T12: Medium-High | U12: https://www.globes.co.il/news/article.aspx?did=1001528671 | V12: Business press | W12: Value undisclosed in public reporting. | AF12: The company was acquired by UVision for an undisclosed amount on November 26, 2025. The acquistion will help the company to sets a precedent for the integration of cutting-edge technologies in defense applications. | AG12: Formerly VC-backed | AH12: Generating Revenue | AI12: UVision Air (Ran Gozali) | AJ12: Aerospace and Defense | AK12: Artificial Intelligence & Machine Learning, Industrials, Robotics and Drones | AL12: Developer of encapsulated aerial weapon systems designed to support maneuvering forces across land, air, and sea operations. The company platform offers AI-enabled personal aerial weapon systems, autonomous or manually controlled deployment options, integration with manned and unmanned vehicles, mesh networking for shared intelligence, and capabilities for instant intelligence, surveillance, reconnaissance, and precision attack missions, providing military organizations and government defense agencies with enhanced battlefield effectiveness, improved operational flexibility, and greater tactical advantage in complex combat environments. | AM12: Tel Aviv, Israel | AN12: www.spearuav.com
B13: Israel | C13: Israel-founded / USA | D13: Wiz | E13: Google / Alphabet | F13: USA | H13: 2025-03-18 | I13: Pending / approvals | J13: 2025 | K13: M&A | L13: Full acquisition | M13: Announced | N13: 32000 | O13: USD | P13: Software | Q13: Cybersecurity | R13: Adjacent cyber-security | S13: Israeli-founded cloud security company; relevant as dual-use cyber/security consolidation, not core A&D. | T13: High | U13: https://blog.google/company-news/inside-google/company-announcements/google-agreement-acquire-wiz/?utm_source=chatgpt.com | V13: Company press release
B14: Israel | C14: Israel | D14: ThirdEye Systems | E14: EDGE Group | F14: UAE | G14: Public / existing shareholders | H14: 2025-01-28 | I14: Pending shareholder approvals / JV setup | J14: 2025 | K14: M&A | L14: MINORITY — 30% stake + JV | M14: Announced | N14: 10.3 | O14: USD | P14: Hardware / Software | Q14: Defense Electronics/Sensors | R14: Core A&D / Defense-electronics adjacent | S14: Adds a rare non-US strategic defense investment into Israeli counter-drone / EO detection technology. | T14: Medium-High | U14: https://www.calcalistech.com/ctechnews/article/t0k36tepz | V14: Reputable press | W14: Minority investment; do not count as full acquisition.
B15: Israel | C15: Israel | D15: Gadfin Aero-Logistics Systems | E15: Israel Acquisitions Corp. | F15: USA / Israel SPAC | G15: Gadfin shareholders / SPAC shareholders | H15: 2025-01-27 | I15: Expected H2 2025 / subject to approvals | J15: 2025 | K15: M&A | L15: OTHER — SPAC / business combination | M15: Announced / pending approvals | N15: 200 | O15: USD | P15: Hardware / Software | Q15: UAVs/Autonomous Systems | R15: Aerospace / UAV-adjacent, not pure defense | S15: Good supplemental aerospace/UAV row, but classify separately because it is a SPAC-style business combination and not a classic defense acquisition. | T15: Medium-High | U15: https://www.unmannedsystemstechnology.com/2025/02/business-combination-agreement-to-improve-drone-delivery/ | V15: Industry press / business-combination announcement | W15: Treat as aerospace/UAV-adjacent and separate from classic M&A counts.
B16: Israel | C16: USA | D16: Stellar Blu Solutions | E16: Gilat Satellite Networks | F16: Israel | H16: 2024-06-17 | I16: 2024-09-18 | J16: 2024 | K16: M&A | L16: Full acquisition | M16: Completed | N16: Not disclosed | O16: USD | P16: Hardware | Q16: Satellite/Space | R16: Adjacent A&D aerospace | S16: Aviation satcom terminal business relevant to aerospace connectivity; dual-use rather than pure defense. | T16: High | U16: https://www.gilat.com/pressreleases/gilat-completes-acquisition-of-stellar-blu-solutions-llc/ | V16: Company press release
B17: Israel | C17: Israel | D17: Noname Security | E17: Akamai Technologies | F17: USA | H17: 2024-05-07 | I17: 2024-06-25 | J17: 2024 | K17: M&A | L17: Full acquisition | M17: Completed | N17: 450 | O17: USD | P17: Software | Q17: Cybersecurity | R17: Adjacent cyber-security | S17: API-security platform acquired by major security infrastructure company; dual-use cybersecurity relevance. | T17: High | U17: https://www.akamai.com/newsroom/press-release/akamai-completes-acquisition-of-api-security-company-noname?utm_source=chatgpt.com | V17: Company press release
B18: Israel | C18: Israel | D18: Gem Security | E18: Wiz | F18: Israel-founded / USA | H18: 2024-04-10 | J18: 2024 | K18: M&A | L18: Acquisition | M18: Completed | N18: 350 | O18: USD | P18: Software | Q18: Cybersecurity | R18: Adjacent cyber-security | S18: Cloud threat-detection acquisition by Israeli-founded security platform Wiz. | T18: Medium-High | U18: https://www.calcalistech.com/ctechnews/article/bjleedj0t?utm_source=chatgpt.com | V18: Company blog / press
B19: Israel | C19: Israel | D19: Flow Security | E19: CrowdStrike | F19: USA | H19: 2024-03-05 | J19: 2024 | K19: M&A | L19: Acquisition | M19: Completed | N19: 200 | O19: USD | P19: Software | Q19: Cybersecurity | R19: Adjacent cyber-security | S19: Cloud data-security acquisition by CrowdStrike; relevant to cyber/security but not pure A&D. | T19: Medium-High | V19: Company press release | W19: Reported value from business press.
B20: Israel | C20: Israel | D20: Spera Security | E20: Okta | F20: USA | H20: 2023-12-19 | I20: 2024-02-01 | J20: 2024 | K20: M&A | L20: Acquisition | M20: Completed | N20: 110 | O20: USD | P20: Software | Q20: Cybersecurity | R20: Adjacent cyber-security | S20: Identity-security posture management; relevant to cyber/zero-trust security. | T20: High | V20: Company press release
B21: Israel | C21: Israel | D21: Silk Security | E21: Armis | F21: Israel / USA | H21: 2024-04-17 | J21: 2024 | K21: M&A | L21: Acquisition | M21: Completed | N21: 150 | O21: USD | P21: Software | Q21: Cybersecurity | R21: Adjacent cyber-security | S21: Cyber-risk prioritization platform acquired by Armis; security-adjacent. | T21: High | V21: Company press release | W21: Reported value from business press.
B22: Israel | C22: Israel | D22: Authomize | E22: Delinea | F22: USA | H22: 2024-01-09 | I22: 2024-02-01 | J22: 2024 | K22: M&A | L22: Acquisition | M22: Completed | N22: Not disclosed | O22: USD | P22: Software | Q22: Cybersecurity | R22: Adjacent cyber-security | S22: Identity-security and threat-detection acquisition; cyber-security fit. | T22: High | V22: Company press release
B23: Israel | C23: Israel | D23: Iron Drone | E23: Airobotics / Ondas Holdings | F23: Israel / USA | H23: 2023-03-06 | J23: 2023 | K23: M&A | L23: Acquisition | M23: Completed | N23: Not disclosed | O23: USD | P23: Hardware/Software | Q23: UAVs/Autonomous Systems | R23: Core A&D | S23: Counter-drone interception and autonomous drone capabilities relevant to security and defense. | T23: Medium | U23: https://ir.ondas.com/press-releases/detail/172/ondas-receives-8-0-million-purchase-order-for-iron-drone | V23: Company press release | W23: Use if source URL resolves in browser. | AF23: The company was acquired by Airobotics (TAE: AIRO) for an undisclosed amount on March 6, 2023. The acquisition integrates counter-drone technology with Airobotics's networked optimus urban drone infrastructure. | AG23: Corporate Backed or Acquired | AH23: Generating Revenue | AI23: Airobotics (Meir Kliner) | AJ23: Automation/Workflow Software | AK23: Robotics and Drones | AL23: Developer of autonomous counter-drone system catering to unmanned aircraft infrastructure. The technology is capable of being integrated into the existing detection and radar infrastructure to provide an autonomous response for the interception of hostile, small drones, which pose real threats to strategic facilities around the world. | AM23: Tel Aviv, Israel | AN23: www.irondrone.com
B24: Israel | C24: USA | D24: DataPath | E24: Gilat Satellite Networks | F24: Israel | G24: DataPath shareholders | H24: 2023-03-09 | I24: 2023-11-15 | J24: 2023 | K24: M&A | L24: Full acquisition | M24: Completed | N24: Not disclosed | O24: USD | P24: Hardware/Services | Q24: Satellite/Space | R24: Core A&D | S24: US satellite communications systems provider serving defense and government customers acquired by Israeli satcom group. | T24: High | U24: https://www.gilat.com/pressreleases/gilat-completes-acquisition-of-datapath/ | V24: Company press release
B25: Israel | C25: Israel | D25: Dig Security | E25: Palo Alto Networks | F25: USA | H25: 2023-10-31 | J25: 2023 | K25: M&A | L25: Acquisition | M25: Completed | N25: 350 | O25: USD | P25: Software | Q25: Cybersecurity | R25: Adjacent cyber-security | S25: Israeli cybersecurity acquisition; relevant to security/dual-use cyber but not pure defense. | T25: Medium-High | U25: https://www.paloaltonetworks.com/company/press/2023/palo-alto-networks-completes-acquisition-of-dig-security?utm_source=chatgpt.com | V25: Legal adviser / business press | W25: Value usually reported as $300m-$400m; use midpoint.
B26: Israel | C26: Israel | D26: Talon Cyber Security | E26: Palo Alto Networks | F26: USA | H26: 2023-11-06 | J26: 2023 | K26: M&A | L26: Acquisition | M26: Completed | N26: 625 | O26: USD | P26: Software | Q26: Cybersecurity | R26: Adjacent cyber-security | S26: Browser-security acquisition; relevant to cyber/security consolidation. | T26: Medium-High | U26: https://www.calcalistech.com/ctechnews/article/r1hd0o87a?utm_source=chatgpt.com | V26: Business press | W26: Reported value.
B27: Israel | C27: Israel | D27: Perimeter 81 | E27: Check Point Software Technologies | F27: Israel | H27: 2023-08-10 | I27: 2023-09-11 | J27: 2023 | K27: M&A | L27: Acquisition | M27: Completed | N27: 490 | O27: USD | P27: Software | Q27: Cybersecurity | R27: Adjacent cyber-security | S27: Israeli network-security/SASE acquisition; relevant to homeland-security and enterprise-cyber landscape. | T27: High | U27: https://www.checkpoint.com/press-releases/check-point-to-acquire-perimeter-81-to-deliver-the-fastest-and-most-secure-sase-solution-in-the-industry/?utm_source=chatgpt.com | V27: Company press release
B28: Israel | C28: Israel | D28: Ermetic | E28: Tenable | F28: USA | H28: 2023-09-07 | I28: 2023-10-02 | J28: 2023 | K28: M&A | L28: Acquisition | M28: Completed | N28: 265 | O28: USD | P28: Software | Q28: Cybersecurity | R28: Adjacent cyber-security | S28: Cloud security and identity-risk platform; dual-use cyber relevance. | T28: High | U28: https://www.tenable.com/press-releases/tenable-announces-intent-to-acquire-ermetic?utm_source=chatgpt.com | V28: Company press release
B29: Israel | C29: Israel | D29: Axis Security | E29: Hewlett Packard Enterprise | F29: USA | H29: 2023-03-02 | I29: 2023-03-31 | J29: 2023 | K29: M&A | L29: Acquisition | M29: Completed | N29: 500 | O29: USD | P29: Software | Q29: Cybersecurity | R29: Adjacent cyber-security | S29: Secure access / edge cybersecurity relevant to security infrastructure; not pure A&D. | T29: Medium-High | U29: https://en.globes.co.il/en/article-hpe-buys-israeli-co-axis-security-for-500m-1001440101?utm_source=chatgpt.com | V29: Company press release | W29: Reported value from business press; official release may not disclose price.
B30: Israel | C30: Israel | D30: Laminar | E30: Rubrik | F30: USA | H30: 2023-08-08 | J30: 2023 | K30: M&A | L30: Acquisition | M30: Completed | N30: 200 | O30: USD | P30: Software | Q30: Cybersecurity | R30: Adjacent cyber-security | S30: Cloud data-security acquisition; dual-use cyber relevance. | T30: High | V30: Company press release | W30: Reported value around $200m-$250m.
B31: Israel | C31: Israel | D31: Bionic | E31: CrowdStrike | F31: USA | H31: 2023-09-19 | J31: 2023 | K31: M&A | L31: Acquisition | M31: Completed | N31: 350 | O31: USD | P31: Software | Q31: Cybersecurity | R31: Adjacent cyber-security | S31: Israeli app-security company acquired by CrowdStrike; security-adjacent. | T31: High | V31: Company press release
B32: Israel | C32: Israel | D32: SCADAfence | E32: Honeywell | F32: USA | H32: 2023-07-10 | I32: 2023-08-14 | J32: 2023 | K32: M&A | L32: Acquisition | M32: Completed | N32: Not disclosed | O32: USD | P32: Software | Q32: Cybersecurity | R32: Adjacent cyber / critical infrastructure | S32: OT cybersecurity for industrial and critical infrastructure environments; strong homeland-security relevance. | T32: High | V32: Company press release
B33: Israel | C33: Israel | D33: Enso Security | E33: Snyk | F33: UK / USA | H33: 2023-06-20 | J33: 2023 | K33: M&A | L33: Acquisition | M33: Completed | N33: 32.7 | O33: USD | P33: Software | Q33: Cybersecurity | R33: Adjacent cyber-security | S33: Israeli application-security posture management acquired by Snyk; cyber-security fit. | T33: High | V33: Company press release
B34: Israel | C34: Greece | D34: Intracom Defense (IDE) | E34: Israel Aerospace Industries (IAI) | F34: Israel | G34: Intracom Holdings / shareholders | H34: 2023-05-09 | I34: Expected Q2 2023 | J34: 2023 | K34: M&A | L34: MAJORITY — 90.91% stake | M34: Signed / expected close | N34: 66 | O34: USD | P34: Hardware / Software | Q34: Defense Electronics/Sensors | R34: Core A&D | S34: Adds a non-cyber Israeli-acquirer transaction. Useful only if the Israel dataset includes Israeli buyers, not just Israeli targets. | T34: Medium-High | U34: https://www.iai.co.il/press/iai-has-acquired-greek-defence-company-intracom-defence/ | V34: Company press release + press estimate | W34: Target country is Greece, not Israel; include only under Israeli-acquirer logic.
B35: Israel | C35: Israel | D35: S.P.O. Smart Precision Optics | E35: Ondas Inc. | F35: USA | G35: Shamir Investment Entrepreneurship ACS Ltd. | H35: 2025-08-26 | I35: 2025-10-03 | J35: 2025 | K35: M&A | L35: MINORITY / controlling stake | M35: Completed | N35: 6 | O35: USD | P35: Hardware | Q35: Defense Electronics/Sensors | R35: Core A&D | S35: Precision optics are relevant to electro-optical systems, missile defense and counter-drone applications. | T35: High | U35: https://ir.ondas.com/press-releases/detail/233/ondas-holdings-enters-definitive-agreement-to-acquire | V35: Company press release / SEC filing | W35: Ondas annual report states SPO acquisition completed Oct. 3, 2025; value shown from pasted list, verify against filings if used. | AE35: 3.48 | AF35: The company was acquired by Ondas (NAS: ONDS) for approximately ILS 6 million on October 3, 2025. Ondas Holdings aims to strengthen its leadership in advanced defense technologies. | AG35: Corporate Backed or Acquired | AH35: Generating Revenue | AI35: Ondas (NAS: ONDS) (Eric Brock) | AJ35: Other Commercial Products | AK35: Augmented Reality, Manufacturing | AL35: Manufacturer and developer of precision optical components intended for various high-tech applications based in Shamir, Israel. The company designs, produces, and measures cylindrical, acylindrical, toric, atoric, and freeform optics using contour fabrication techniques, serving industries such as space, defense, medical, Augmented Reality/Visual Reality, and automotive. | AM35: Shamir, Israel | AN35: www.spo.tech
B36: Israel | C36: Israel | D36: Insight Intelligent Sensors | E36: Ondas Inc. | F36: USA | H36: 2025-10-29 | I36: 2025 | J36: 2025 | K36: M&A | L36: MINORITY / controlling stake | M36: Completed | N36: 3.5 | O36: USD | P36: Hardware | Q36: Defense Electronics/Sensors | R36: Core A&D | S36: AI-powered electro-optical sensing strengthens counter-UAS, surveillance and early-warning capabilities. | T36: High | U36: https://www.ondas.com/post/ondas-expands-its-ai-sensing-capabilities-with-the-acquisition-of-a-controlling-interest-in-insight | V36: Company press release | W36: Value from pasted list; source confirms acquisition/relevance, value should be double-checked in filing if needed. | AE36: 6.86 | AF36: The company was acquired by Ondas (NAS: ONDS) for $3.5 million on October 27, 2025. This acquisition strengthens Ondas' ability to deliver advanced autonomy and sensing across multiple domains and positions the Company for new government and commercial programs in autonomous detection and environmental intelligence. | AG36: Corporate Backed or Acquired | AH36: Generating Revenue | AI36: Ondas (NAS: ONDS) (Eric Brock) | AJ36: Aerospace and Defense | AK36: Manufacturing | AL36: Manufacturer and designer of artificial intelligence-powered electro-optical systems for real-time anomaly detection in complex environments serving the military and defence industries. The company offers technology-integrated security solutions addressing emerging needs in ISR, border security, critical infrastructure protection, and environmental resilience. | AM36: Rehovot, Israel
B37: Israel | C37: Israel | D37: Opgal | E37: Gevasol Group | F37: Israel | H37: 2025-08-01 | I37: 2025-08-01 | J37: 2025 | K37: M&A | L37: FULL | M37: Completed | N37: Not disclosed | O37: USD | P37: Hardware | Q37: Defense Electronics/Sensors | R37: Defense-adjacent | S37: Opgal develops thermal cameras and electro-optical systems for industrial, HLS/security and defense uses; acquisition is less pure defense but relevant electro-optics. | T37: Medium-High | U37: https://www.opgal.com/blog/%D7%9B%D7%9C%D7%9C%D7%99/gevasol-acquires-opgal-to-expand-portfolio-into-advanced-emission-monitoring-and-reduction-technologies/ | V37: Company announcement | W37: Source focuses on emission monitoring; keep as defense-adjacent, not core A&D. | AF37: The company was acquired by Gevasol for an undisclosed amount on August 1, 2025. The acquisition enhances Gevasol's portfolio of engineered systems and precision components. | AG37: Corporate Backed or Acquired | AH37: Generating Revenue | AI37: Gevasol (Gideon Yadin) | AJ37: Electrical Equipment | AK37: Manufacturing | AL37: Manufacturer of infrared imaging systems and optical gas detection technologies serving industrial, oil and gas, environmental, and defense sectors. The company offers optical gas imaging cameras, thermographic imaging systems, multi-spectral filters, gas quantification software, real-time streaming tools, and wireless connectivity features, helping users detect volatile organic compounds, monitor emissions, and ensure safety and compliance in harsh operating environments. | AM37: Karmiel, Israel | AN37: www.opgal.com
B38: Israel | C38: Israel | D38: Enercon Technologies | E38: Bel Fuse | F38: USA | G38: Fortissimo Capital / shareholders | H38: 2024-09-18 | I38: 2024-11-14 | J38: 2024 | K38: M&A | L38: MINORITY / controlling 80% stake | M38: Completed | N38: 324 | O38: USD | P38: Hardware | Q38: Power/Components | R38: Core A&D | S38: Enercon designs power conversion/networking solutions for military and aerospace applications; Bel acquired majority stake. | T38: High | U38: https://ir.belfuse.com/news-releases/news-release-details/bel-announces-agreement-acquire-enercon-technologies | V38: Company press release / SEC filing | W38: Use 80% stake / majority acquisition, not full acquisition. | AE38: 324 | AF38: The company was acquired by Bel Fuse (NASDAQ: BELFB) for approximately $324 million on November 14, 2024. The company will receive a contingent payout of $10 million based on earnout payments for the 2025-2026 period. The acquisition will allow Bel Fuse to extend its product portfolio, supporting the aerospace and defense markets. | AG38: Formerly PE-Backed | AH38: Generating Revenue | AI38: Bel Fuse (NAS: BELFB) (Daniel Bernstein) | AJ38: Aerospace and Defense | AK38: Manufacturing | AL38: Manufacturer of power supplies intended to serve the military, civilian aerospace and aircraft markets. The company offers ethernet switches, routers, inverters, storage devices, universal serial bus (USB) hubs and embedded accessories, enabling clients to have customized power supplies produced in accordance with specific requests and constraints. | AM38: Netanya, Israel | AN38: www.enercon.co.il
B39: Israel | C39: Israel | D39: Israeli Industrial Batteries | E39: Sunlight Group | F39: Greece / EU | H39: 2023-02-14 | I39: 2023-02-14 | J39: 2023 | K39: M&A | L39: MINORITY / 51% stake | M39: Completed | N39: Not disclosed | O39: USD | P39: Hardware | Q39: Power/Components | R39: Defense-adjacent | S39: Battery company relevant to defense/industrial power supply chain; include only as defense-adjacent, not core platform A&D. | T39: Medium | U39: https://www.linkedin.com/posts/sunlight-group-energy-storage-systems_partnership-acquisition-growth-activity-7031232903506255873-khvk | V39: Company LinkedIn / secondary source | W39: Source says Sunlight acquired 51% stake; no deal value disclosed. | AF39: The company was acquired by The Sunlight Group for an undisclosed amount on February 14, 2023. The acquisition will help in The Sunlight Group's objective for global leadership in motive power batteries for the intralogistics sector and energy storage systems for renewables and expands their geographical reach in the MENA region. | AG39: Corporate Backed or Acquired | AH39: Generating Revenue | AI39: Systems Sunlight (Lampros Bisalas) | AJ39: Electrical Equipment | AK39: Manufacturing | AL39: Manufacturer and supplier of industrial batteries catering to telecom, aerospace and defense sectors. The company offers chargers, solar systems, ups, traction, telecom, railway, special and lithium-ion batteries as well as battery room equipment. | AM39: Nahariya, Israel | AN39: eng.iib.co.il
B40: Israel | C40: Israel | D40: DSIT Solutions | E40: IPO / Public listing | F40: Israel | H40: 2026-03-12 | I40: 2026-03-12 | J40: 2026 | K40: IPO | L40: OTHER | M40: Completed / listed | N40: Not disclosed | O40: USD | P40: Hardware | Q40: Maritime Systems | R40: Core A&D public-market transaction | S40: Rafael underwater surveillance subsidiary; sonar, diver detection, ASW and underwater security systems. | T40: Medium-High | U40: https://www.tradingview.com/symbols/TASE-DSIT/ | V40: Market data / company profile | W40: IPO/public-market row, not M&A. Deal value from pasted list was blank; fill only from prospectus/TASE if needed. | AF40: The company completed its initial public offering on the Tel Aviv Stock Exchange under the ticker symbol of DSIT on March 13, 2026. | AG40: Corporate Backed or Acquired | AH40: Profitable | AJ40: Aerospace and Defense | AK40: Industrials | AL40: DSIT Solutions Ltd is a technological company specializing in underwater technology solutions. It has developed and implemented comprehensive defense and protection solutions against various underwater threats, focusing on six main types of solutions: Underwater Domain Awareness, Underwater Security, Anti-Submarine Warfare (ASW) Systems for Surface Ships, Trainers, PAR & Acoustic Signal Analysis (ASA) Systems, and Underwater Communication Systems. | AM40: Givat Shmuel, Israel | AN40: www.dsit.co.il
...

Sheet USA
A1: Deal ID | B1: Region | C1: Target Country | D1: Target / Asset | E1: Acquirer | F1: Acquirer Country | G1: Seller | H1: Announcement Date | I1: Completion Date | J1: Deal Year | K1: Transaction Type | L1: Deal Structure | M1: Deal Status | N1: Deal Value (USD mn) | O1: Currency | P1: Implied EV/Revenue | Q1: Implied EV/EBITDA | R1: Deal Size/EBITDA | S1: EBITDA | T1: Deal Size/Revenue | U1: Revenue | V1: Deal Type 2 | W1: Post Valuation | X1: Deal Synopsis | Y1: Financing Status | Z1: Business Status | AA1: Investors | AB1: Primary PitchBook Industry Code | AC1: Verticals | AD1: Description | AE1: HQ Location | AF1: Company Website
